Workbook

Sheet Parameters
A1: Parameter | B1: Value | C1: Description
A2: price_per_instance | B2: 9 | C2: Monthly price per wedding instance
A3: payment_fee_rate | B3: 0.1 | C3: Payment processor fee rate
A4: alpha | B4: 0.2 | C4: Revenue share percentage
A5: k | B5: 0.5 | C5: Price constant for token pricing
A6: base_new_instances | B6: 8 | C6: Base new instances per month
A7: growth_trend_end | B7: 40 | C7: Additional new instances by month 60
A8: avg_lifetime_months | B8: 5 | C8: Average customer lifetime
A9: sell_pressure | B9: 0.1 | C9: Fraction of token supply sold monthly
A10: months | B10: 60 | C10: Simulation length in months

Sheet Simulation
A1: Month | B1: New Instances | C1: Active Instances | D1: Net Revenue ($) | E1: Cumulative Revenue ($) | F1: Token Price ($) | G1: Tokens Minted | H1: Tokens Burned | I1: Token Supply | J1: Monthly Payout Pool ($) | K1: Payout per Token ($)
A2: 1 | B2: =Parameters!B6 + SIN(1/60*10*PI())*5 + (1/60)*Parameters!B7 | C2: =B2 | D2: =C2*Parameters!B2*(1-Parameters!B3) | E2: =D2 | F2: =Parameters!B5*SQRT(E2) | G2: =(Parameters!B4*D2)/F2 | H2: 0 | I2: =G2 | J2: =Parameters!B4*D2 | K2: =IF(I2>0,J2/I2,0)
A3: 2 | B3: =Parameters!B6 + SIN(2/60*10*PI())*5 + (2/60)*Parameters!B7 | C3: =C2*(1-1/Parameters!B8)+B3 | D3: =C3*Parameters!B2*(1-Parameters!B3) | E3: =E2+D3 | F3: =Parameters!B5*SQRT(E3) | G3: =(Parameters!B4*D3)/F3 | H3: =I2*Parameters!B9 | I3: =I2+G3-H3 | J3: =Parameters!B4*D3 | K3: =IF(I3>0,J3/I3,0)
A4: 3 | B4: =Parameters!B6 + SIN(3/60*10*PI())*5 + (3/60)*Parameters!B7 | C4: =C3*(1-1/Parameters!B8)+B4 | D4: =C4*Parameters!B2*(1-Parameters!B3) | E4: =E3+D4 | F4: =Parameters!B5*SQRT(E4) | G4: =(Parameters!B4*D4)/F4 | H4: =I3*Parameters!B9 | I4: =I3+G4-H4 | J4: =Parameters!B4*D4 | K4: =IF(I4>0,J4/I4,0)
A5: 4 | B5: =Parameters!B6 + SIN(4/60*10*PI())*5 + (4/60)*Parameters!B7 | C5: =C4*(1-1/Parameters!B8)+B5 | D5: =C5*Parameters!B2*(1-Parameters!B3) | E5: =E4+D5 | F5: =Parameters!B5*SQRT(E5) | G5: =(Parameters!B4*D5)/F5 | H5: =I4*Parameters!B9 | I5: =I4+G5-H5 | J5: =Parameters!B4*D5 | K5: =IF(I5>0,J5/I5,0)
A6: 5 | B6: =Parameters!B6 + SIN(5/60*10*PI())*5 + (5/60)*Parameters!B7 | C6: =C5*(1-1/Parameters!B8)+B6 | D6: =C6*Parameters!B2*(1-Parameters!B3) | E6: =E5+D6 | F6: =Parameters!B5*SQRT(E6) | G6: =(Parameters!B4*D6)/F6 | H6: =I5*Parameters!B9 | I6: =I5+G6-H6 | J6: =Parameters!B4*D6 | K6: =IF(I6>0,J6/I6,0)
A7: 6 | B7: =Parameters!B6 + SIN(6/60*10*PI())*5 + (6/60)*Parameters!B7 | C7: =C6*(1-1/Parameters!B8)+B7 | D7: =C7*Parameters!B2*(1-Parameters!B3) | E7: =E6+D7 | F7: =Parameters!B5*SQRT(E7) | G7: =(Parameters!B4*D7)/F7 | H7: =I6*Parameters!B9 | I7: =I6+G7-H7 | J7: =Parameters!B4*D7 | K7: =IF(I7>0,J7/I7,0)
A8: 7 | B8: =Parameters!B6 + SIN(7/60*10*PI())*5 + (7/60)*Parameters!B7 | C8: =C7*(1-1/Parameters!B8)+B8 | D8: =C8*Parameters!B2*(1-Parameters!B3) | E8: =E7+D8 | F8: =Parameters!B5*SQRT(E8) | G8: =(Parameters!B4*D8)/F8 | H8: =I7*Parameters!B9 | I8: =I7+G8-H8 | J8: =Parameters!B4*D8 | K8: =IF(I8>0,J8/I8,0)
A9: 8 | B9: =Parameters!B6 + SIN(8/60*10*PI())*5 + (8/60)*Parameters!B7 | C9: =C8*(1-1/Parameters!B8)+B9 | D9: =C9*Parameters!B2*(1-Parameters!B3) | E9: =E8+D9 | F9: =Parameters!B5*SQRT(E9) | G9: =(Parameters!B4*D9)/F9 | H9: =I8*Parameters!B9 | I9: =I8+G9-H9 | J9: =Parameters!B4*D9 | K9: =IF(I9>0,J9/I9,0)
A10: 9 | B10: =Parameters!B6 + SIN(9/60*10*PI())*5 + (9/60)*Parameters!B7 | C10: =C9*(1-1/Parameters!B8)+B10 | D10: =C10*Parameters!B2*(1-Parameters!B3) | E10: =E9+D10 | F10: =Parameters!B5*SQRT(E10) | G10: =(Parameters!B4*D10)/F10 | H10: =I9*Parameters!B9 | I10: =I9+G10-H10 | J10: =Parameters!B4*D10 | K10: =IF(I10>0,J10/I10,0)
A11: 10 | B11: =Parameters!B6 + SIN(10/60*10*PI())*5 + (10/60)*Parameters!B7 | C11: =C10*(1-1/Parameters!B8)+B11 | D11: =C11*Parameters!B2*(1-Parameters!B3) | E11: =E10+D11 | F11: =Parameters!B5*SQRT(E11) | G11: =(Parameters!B4*D11)/F11 | H11: =I10*Parameters!B9 | I11: =I10+G11-H11 | J11: =Parameters!B4*D11 | K11: =IF(I11>0,J11/I11,0)
A12: 11 | B12: =Parameters!B6 + SIN(11/60*10*PI())*5 + (11/60)*Parameters!B7 | C12: =C11*(1-1/Parameters!B8)+B12 | D12: =C12*Parameters!B2*(1-Parameters!B3) | E12: =E11+D12 | F12: =Parameters!B5*SQRT(E12) | G12: =(Parameters!B4*D12)/F12 | H12: =I11*Parameters!B9 | I12: =I11+G12-H12 | J12: =Parameters!B4*D12 | K12: =IF(I12>0,J12/I12,0)
A13: 12 | B13: =Parameters!B6 + SIN(12/60*10*PI())*5 + (12/60)*Parameters!B7 | C13: =C12*(1-1/Parameters!B8)+B13 | D13: =C13*Parameters!B2*(1-Parameters!B3) | E13: =E12+D13 | F13: =Parameters!B5*SQRT(E13) | G13: =(Parameters!B4*D13)/F13 | H13: =I12*Parameters!B9 | I13: =I12+G13-H13 | J13: =Parameters!B4*D13 | K13: =IF(I13>0,J13/I13,0)
A14: 13 | B14: =Parameters!B6 + SIN(13/60*10*PI())*5 + (13/60)*Parameters!B7 | C14: =C13*(1-1/Parameters!B8)+B14 | D14: =C14*Parameters!B2*(1-Parameters!B3) | E14: =E13+D14 | F14: =Parameters!B5*SQRT(E14) | G14: =(Parameters!B4*D14)/F14 | H14: =I13*Parameters!B9 | I14: =I13+G14-H14 | J14: =Parameters!B4*D14 | K14: =IF(I14>0,J14/I14,0)
A15: 14 | B15: =Parameters!B6 + SIN(14/60*10*PI())*5 + (14/60)*Parameters!B7 | C15: =C14*(1-1/Parameters!B8)+B15 | D15: =C15*Parameters!B2*(1-Parameters!B3) | E15: =E14+D15 | F15: =Parameters!B5*SQRT(E15) | G15: =(Parameters!B4*D15)/F15 | H15: =I14*Parameters!B9 | I15: =I14+G15-H15 | J15: =Parameters!B4*D15 | K15: =IF(I15>0,J15/I15,0)
A16: 15 | B16: =Parameters!B6 + SIN(15/60*10*PI())*5 + (15/60)*Parameters!B7 | C16: =C15*(1-1/Parameters!B8)+B16 | D16: =C16*Parameters!B2*(1-Parameters!B3) | E16: =E15+D16 | F16: =Parameters!B5*SQRT(E16) | G16: =(Parameters!B4*D16)/F16 | H16: =I15*Parameters!B9 | I16: =I15+G16-H16 | J16: =Parameters!B4*D16 | K16: =IF(I16>0,J16/I16,0)
A17: 16 | B17: =Parameters!B6 + SIN(16/60*10*PI())*5 + (16/60)*Parameters!B7 | C17: =C16*(1-1/Parameters!B8)+B17 | D17: =C17*Parameters!B2*(1-Parameters!B3) | E17: =E16+D17 | F17: =Parameters!B5*SQRT(E17) | G17: =(Parameters!B4*D17)/F17 | H17: =I16*Parameters!B9 | I17: =I16+G17-H17 | J17: =Parameters!B4*D17 | K17: =IF(I17>0,J17/I17,0)
A18: 17 | B18: =Parameters!B6 + SIN(17/60*10*PI())*5 + (17/60)*Parameters!B7 | C18: =C17*(1-1/Parameters!B8)+B18 | D18: =C18*Parameters!B2*(1-Parameters!B3) | E18: =E17+D18 | F18: =Parameters!B5*SQRT(E18) | G18: =(Parameters!B4*D18)/F18 | H18: =I17*Parameters!B9 | I18: =I17+G18-H18 | J18: =Parameters!B4*D18 | K18: =IF(I18>0,J18/I18,0)
A19: 18 | B19: =Parameters!B6 + SIN(18/60*10*PI())*5 + (18/60)*Parameters!B7 | C19: =C18*(1-1/Parameters!B8)+B19 | D19: =C19*Parameters!B2*(1-Parameters!B3) | E19: =E18+D19 | F19: =Parameters!B5*SQRT(E19) | G19: =(Parameters!B4*D19)/F19 | H19: =I18*Parameters!B9 | I19: =I18+G19-H19 | J19: =Parameters!B4*D19 | K19: =IF(I19>0,J19/I19,0)
A20: 19 | B20: =Parameters!B6 + SIN(19/60*10*PI())*5 + (19/60)*Parameters!B7 | C20: =C19*(1-1/Parameters!B8)+B20 | D20: =C20*Parameters!B2*(1-Parameters!B3) | E20: =E19+D20 | F20: =Parameters!B5*SQRT(E20) | G20: =(Parameters!B4*D20)/F20 | H20: =I19*Parameters!B9 | I20: =I19+G20-H20 | J20: =Parameters!B4*D20 | K20: =IF(I20>0,J20/I20,0)
A21: 20 | B21: =Parameters!B6 + SIN(20/60*10*PI())*5 + (20/60)*Parameters!B7 | C21: =C20*(1-1/Parameters!B8)+B21 | D21: =C21*Parameters!B2*(1-Parameters!B3) | E21: =E20+D21 | F21: =Parameters!B5*SQRT(E21) | G21: =(Parameters!B4*D21)/F21 | H21: =I20*Parameters!B9 | I21: =I20+G21-H21 | J21: =Parameters!B4*D21 | K21: =IF(I21>0,J21/I21,0)
A22: 21 | B22: =Parameters!B6 + SIN(21/60*10*PI())*5 + (21/60)*Parameters!B7 | C22: =C21*(1-1/Parameters!B8)+B22 | D22: =C22*Parameters!B2*(1-Parameters!B3) | E22: =E21+D22 | F22: =Parameters!B5*SQRT(E22) | G22: =(Parameters!B4*D22)/F22 | H22: =I21*Parameters!B9 | I22: =I21+G22-H22 | J22: =Parameters!B4*D22 | K22: =IF(I22>0,J22/I22,0)
A23: 22 | B23: =Parameters!B6 + SIN(22/60*10*PI())*5 + (22/60)*Parameters!B7 | C23: =C22*(1-1/Parameters!B8)+B23 | D23: =C23*Parameters!B2*(1-Parameters!B3) | E23: =E22+D23 | F23: =Parameters!B5*SQRT(E23) | G23: =(Parameters!B4*D23)/F23 | H23: =I22*Parameters!B9 | I23: =I22+G23-H23 | J23: =Parameters!B4*D23 | K23: =IF(I23>0,J23/I23,0)
A24: 23 | B24: =Parameters!B6 + SIN(23/60*10*PI())*5 + (23/60)*Parameters!B7 | C24: =C23*(1-1/Parameters!B8)+B24 | D24: =C24*Parameters!B2*(1-Parameters!B3) | E24: =E23+D24 | F24: =Parameters!B5*SQRT(E24) | G24: =(Parameters!B4*D24)/F24 | H24: =I23*Parameters!B9 | I24: =I23+G24-H24 | J24: =Parameters!B4*D24 | K24: =IF(I24>0,J24/I24,0)
A25: 24 | B25: =Parameters!B6 + SIN(24/60*10*PI())*5 + (24/60)*Parameters!B7 | C25: =C24*(1-1/Parameters!B8)+B25 | D25: =C25*Parameters!B2*(1-Parameters!B3) | E25: =E24+D25 | F25: =Parameters!B5*SQRT(E25) | G25: =(Parameters!B4*D25)/F25 | H25: =I24*Parameters!B9 | I25: =I24+G25-H25 | J25: =Parameters!B4*D25 | K25: =IF(I25>0,J25/I25,0)
A26: 25 | B26: =Parameters!B6 + SIN(25/60*10*PI())*5 + (25/60)*Parameters!B7 | C26: =C25*(1-1/Parameters!B8)+B26 | D26: =C26*Parameters!B2*(1-Parameters!B3) | E26: =E25+D26 | F26: =Parameters!B5*SQRT(E26) | G26: =(Parameters!B4*D26)/F26 | H26: =I25*Parameters!B9 | I26: =I25+G26-H26 | J26: =Parameters!B4*D26 | K26: =IF(I26>0,J26/I26,0)
A27: 26 | B27: =Parameters!B6 + SIN(26/60*10*PI())*5 + (26/60)*Parameters!B7 | C27: =C26*(1-1/Parameters!B8)+B27 | D27: =C27*Parameters!B2*(1-Parameters!B3) | E27: =E26+D27 | F27: =Parameters!B5*SQRT(E27) | G27: =(Parameters!B4*D27)/F27 | H27: =I26*Parameters!B9 | I27: =I26+G27-H27 | J27: =Parameters!B4*D27 | K27: =IF(I27>0,J27/I27,0)
A28: 27 | B28: =Parameters!B6 + SIN(27/60*10*PI())*5 + (27/60)*Parameters!B7 | C28: =C27*(1-1/Parameters!B8)+B28 | D28: =C28*Parameters!B2*(1-Parameters!B3) | E28: =E27+D28 | F28: =Parameters!B5*SQRT(E28) | G28: =(Parameters!B4*D28)/F28 | H28: =I27*Parameters!B9 | I28: =I27+G28-H28 | J28: =Parameters!B4*D28 | K28: =IF(I28>0,J28/I28,0)
A29: 28 | B29: =Parameters!B6 + SIN(28/60*10*PI())*5 + (28/60)*Parameters!B7 | C29: =C28*(1-1/Parameters!B8)+B29 | D29: =C29*Parameters!B2*(1-Parameters!B3) | E29: =E28+D29 | F29: =Parameters!B5*SQRT(E29) | G29: =(Parameters!B4*D29)/F29 | H29: =I28*Parameters!B9 | I29: =I28+G29-H29 | J29: =Parameters!B4*D29 | K29: =IF(I29>0,J29/I29,0)
A30: 29 | B30: =Parameters!B6 + SIN(29/60*10*PI())*5 + (29/60)*Parameters!B7 | C30: =C29*(1-1/Parameters!B8)+B30 | D30: =C30*Parameters!B2*(1-Parameters!B3) | E30: =E29+D30 | F30: =Parameters!B5*SQRT(E30) | G30: =(Parameters!B4*D30)/F30 | H30: =I29*Parameters!B9 | I30: =I29+G30-H30 | J30: =Parameters!B4*D30 | K30: =IF(I30>0,J30/I30,0)
A31: 30 | B31: =Parameters!B6 + SIN(30/60*10*PI())*5 + (30/60)*Parameters!B7 | C31: =C30*(1-1/Parameters!B8)+B31 | D31: =C31*Parameters!B2*(1-Parameters!B3) | E31: =E30+D31 | F31: =Parameters!B5*SQRT(E31) | G31: =(Parameters!B4*D31)/F31 | H31: =I30*Parameters!B9 | I31: =I30+G31-H31 | J31: =Parameters!B4*D31 | K31: =IF(I31>0,J31/I31,0)
A32: 31 | B32: =Parameters!B6 + SIN(31/60*10*PI())*5 + (31/60)*Parameters!B7 | C32: =C31*(1-1/Parameters!B8)+B32 | D32: =C32*Parameters!B2*(1-Parameters!B3) | E32: =E31+D32 | F32: =Parameters!B5*SQRT(E32) | G32: =(Parameters!B4*D32)/F32 | H32: =I31*Parameters!B9 | I32: =I31+G32-H32 | J32: =Parameters!B4*D32 | K32: =IF(I32>0,J32/I32,0)
A33: 32 | B33: =Parameters!B6 + SIN(32/60*10*PI())*5 + (32/60)*Parameters!B7 | C33: =C32*(1-1/Parameters!B8)+B33 | D33: =C33*Parameters!B2*(1-Parameters!B3) | E33: =E32+D33 | F33: =Parameters!B5*SQRT(E33) | G33: =(Parameters!B4*D33)/F33 | H33: =I32*Parameters!B9 | I33: =I32+G33-H33 | J33: =Parameters!B4*D33 | K33: =IF(I33>0,J33/I33,0)
A34: 33 | B34: =Parameters!B6 + SIN(33/60*10*PI())*5 + (33/60)*Parameters!B7 | C34: =C33*(1-1/Parameters!B8)+B34 | D34: =C34*Parameters!B2*(1-Parameters!B3) | E34: =E33+D34 | F34: =Parameters!B5*SQRT(E34) | G34: =(Parameters!B4*D34)/F34 | H34: =I33*Parameters!B9 | I34: =I33+G34-H34 | J34: =Parameters!B4*D34 | K34: =IF(I34>0,J34/I34,0)
A35: 34 | B35: =Parameters!B6 + SIN(34/60*10*PI())*5 + (34/60)*Parameters!B7 | C35: =C34*(1-1/Parameters!B8)+B35 | D35: =C35*Parameters!B2*(1-Parameters!B3) | E35: =E34+D35 | F35: =Parameters!B5*SQRT(E35) | G35: =(Parameters!B4*D35)/F35 | H35: =I34*Parameters!B9 | I35: =I34+G35-H35 | J35: =Parameters!B4*D35 | K35: =IF(I35>0,J35/I35,0)
A36: 35 | B36: =Parameters!B6 + SIN(35/60*10*PI())*5 + (35/60)*Parameters!B7 | C36: =C35*(1-1/Parameters!B8)+B36 | D36: =C36*Parameters!B2*(1-Parameters!B3) | E36: =E35+D36 | F36: =Parameters!B5*SQRT(E36) | G36: =(Parameters!B4*D36)/F36 | H36: =I35*Parameters!B9 | I36: =I35+G36-H36 | J36: =Parameters!B4*D36 | K36: =IF(I36>0,J36/I36,0)
A37: 36 | B37: =Parameters!B6 + SIN(36/60*10*PI())*5 + (36/60)*Parameters!B7 | C37: =C36*(1-1/Parameters!B8)+B37 | D37: =C37*Parameters!B2*(1-Parameters!B3) | E37: =E36+D37 | F37: =Parameters!B5*SQRT(E37) | G37: =(Parameters!B4*D37)/F37 | H37: =I36*Parameters!B9 | I37: =I36+G37-H37 | J37: =Parameters!B4*D37 | K37: =IF(I37>0,J37/I37,0)
A38: 37 | B38: =Parameters!B6 + SIN(37/60*10*PI())*5 + (37/60)*Parameters!B7 | C38: =C37*(1-1/Parameters!B8)+B38 | D38: =C38*Parameters!B2*(1-Parameters!B3) | E38: =E37+D38 | F38: =Parameters!B5*SQRT(E38) | G38: =(Parameters!B4*D38)/F38 | H38: =I37*Parameters!B9 | I38: =I37+G38-H38 | J38: =Parameters!B4*D38 | K38: =IF(I38>0,J38/I38,0)
A39: 38 | B39: =Parameters!B6 + SIN(38/60*10*PI())*5 + (38/60)*Parameters!B7 | C39: =C38*(1-1/Parameters!B8)+B39 | D39: =C39*Parameters!B2*(1-Parameters!B3) | E39: =E38+D39 | F39: =Parameters!B5*SQRT(E39) | G39: =(Parameters!B4*D39)/F39 | H39: =I38*Parameters!B9 | I39: =I38+G39-H39 | J39: =Parameters!B4*D39 | K39: =IF(I39>0,J39/I39,0)
A40: 39 | B40: =Parameters!B6 + SIN(39/60*10*PI())*5 + (39/60)*Parameters!B7 | C40: =C39*(1-1/Parameters!B8)+B40 | D40: =C40*Parameters!B2*(1-Parameters!B3) | E40: =E39+D40 | F40: =Parameters!B5*SQRT(E40) | G40: =(Parameters!B4*D40)/F40 | H40: =I39*Parameters!B9 | I40: =I39+G40-H40 | J40: =Parameters!B4*D40 | K40: =IF(I40>0,J40/I40,0)
...
